#include <exception>

void foo(void) {
  throw std::exception();
}
